Workbook
Name a: '2d_bc'!$AB$8
Name b: '2d_bc'!$AB$9
Name Connection: '2d_bc'!$AB$1
Name d: '2d_bc'!$AB$6
Name dZ: '2d_zsh'!$AH$8
Name External: '2d_bc'!$AB$2
Name f: '2d_bc'!$AB$5
Name Flags: '2d_bc'!$AB$3
Name grid_factor: '2d_zsh'!$AH$3
Name grid_size: '2d_zsh'!$AH$2
Name LengthFactor: '2d_bc'!$AB$10
Name max_width: '2d_zsh'!$AH$5
Name min_width: '2d_zsh'!$AH$6
Name MinLength: '2d_bc'!$AB$15
Name Name: '2d_bc'!$AB$4
Name PaddingFactor: '2d_zsh'!$AH$11
Name pipe_factor: '2d_zsh'!$AH$4
Name PipeEnds: '2d_zsh'!$AH$14
Name PipeSpacing: '2d_zsh'!$AH$13
Name Shape_Options: '2d_zsh'!$AH$10
Name Shape_width_or_dMax: '2d_zsh'!$AH$9
Name td: '2d_bc'!$AB$7
Name WidthFactor: '2d_bc'!$AB$11
Name Z_shift: '2d_zsh'!$AH$7

Sheet 12D-Road.rpt
A1: ----------------------------------------------------------------------------------------------------------- | K1: Paste the lines in here, do not split to columns
A2: Road centre line "north chinnamon floodway"
A3: -----------------------------------------------------------------------------------------------------------
A4: Crossing Centreline String
A5: Easting Northing Angle Chainage Height Chainage Height Slope% Name
A6: -----------------------------------------------------------------------------------------------------------
A7: 688648.485 7671741.060 0° 0' 0" 445.000 149.001 13.421 147.450 -0.38 "CULVERTS FW->channel nth"
A8: 688680.358 7671609.876 0° 0' 0" 310.000 149.000 16.194 146.802 -0.61 "CULVERTS FW->main channel sth"
A9: -----------------------------------------------------------------------------------------------------------
A11: -----------------------------------------------------------------------------------------------------------
A12: Road centre line "Chinnamon"
A13: -----------------------------------------------------------------------------------------------------------
A14: Crossing Centreline String
... A56: -----------------------------------------------------------------------------------------------------------

Sheet 12D-Culverts.rpt
A1: 12d | B1: pit | C1: 12d | D1: pit | E1: pit | F1: pit | G1: pit | H1: pit | I1: pit | J1: pit | K1: pit | L1: pipe | M1: pipe | N1: pipe | O1: pipe | P1: pipe | Q1: pipe | R1: pipe | S1: pipe | T1: pipe | U1: pipe | V1: pipe | W1: pipe | X1: pipe | Y1: pipe | Z1: pit | AA1: pit | AB1: pit | AC1: pit | AD1: pit | AE1: pit | AF1: pit | AG1: pit | AH1: pit | AI1: pipe | AJ1: pipe | AK1: pipe | AL1: pipe | AM1: pipe
A2: *string id | B2: *pit id | C2: string name | D2: pit name | E2: pit type | F2: pit diameter | G2: pit centre x | H2: pit centre y | I2: cover elev | J2: fs tin | K2: ns tin | L2: pipe type | M2: invert us | N2: invert ds | O2: diameter | P2: width | Q2: number of pipes | R2: separation | S2: calculated pipe length | T2: calculated pipe grade | U2: pipe size | V2: nominal diameter | W2: nominal pipe size | X2: box or pipe size | Y2: *direction | Z2: remarks | AA2: grate level | AB2: cover rl | AC2: setout z | AD2: top rl | AE2: cover rl mode | AF2: grate rl mode | AG2: pit road chainage | AH2: pit road name | AI2: conduit shape | AJ2: pipe colour | AK2: pipe type description | AL2: pipe type remarks | AM2: custom label name
A3: uid | B3: integer | C3: text | D3: text | E3: text | F3: real | G3: real | H3: real | I3: real | J3: text | K3: text | L3: text | M3: real | N3: real | O3: real | P3: real | Q3: integer | R3: real | S3: real | T3: real | U3: text | V3: real | W3: text | X3: text | Y3: integer | Z3: n/a | AA3: real | AB3: real | AC3: real | AD3: real | AE3: integer | AF3: integer | AG3: real | AH3: text | AI3: text | AJ3: integer | AK3: text | AL3: n/a | AM3: n/a
A4: 1256451 | B4: 12 | C4: channel nth | D4: inlet | E4: CULVERT INLET | F4: 0.6 | G4: 688661.53 | H4: 7671744.2 | I4: 148.1 | J4: MTF ROAD FW Turner river | K4: TIN ESL | L4: BC | M4: 147.5 | N4: 147.4 | O4: 0.6 | P4: 1.2 | Q4: 2 | R4: 0 | S4: 26.78095 | T4: 0.3734 | U4: (2x)1200x600 | V4: 0.6 | W4: (2x)1200x600 | X4: 1.2W x 0.6H | Y4: 1 | AA4: 148.1 | AB4: 148.1 | AC4: 148.1 | AD4: 148.1 | AE4: 0 | AF4: 7 | AG4: -9.9e+29 | AI4: Rectangular | AJ4: -1 | AK4: ROCLA QLD RCBC
A5: 1256451 | B5: 13 | C5: channel nth | D5: outlet | E5: CULVERT OUTLET | F5: 0 | G5: 688635.5 | H5: 7671737.9 | I5: 148 | J5: MTF ROAD FW Turner river | K5: TIN ESL | AA5: 148 | AB5: 148 | AC5: 148 | AD5: 148 | AE5: 0 | AF5: 7 | AG5: -9.9e+29

Sheet 1d_nwk-import
A1: wkt_geom | B1: fid | C1: ID | D1: Type | E1: Ignore | F1: UCS | G1: Len_or_ANA | H1: n_nF_Cd | I1: US_Invert | J1: DS_Invert | K1: Form_Loss | L1: pBlockage | M1: Inlet_Type | N1: Conn_1D_2D | O1: Conn_No | P1: Width_or_D | Q1: Height_or_ | R1: Number_of | S1: HConF_or_W | T1: WConF_or_W | U1: EntryC_or_ | V1: ExitC_or_W
A2: MultiLineString ((687316.367809071787633 7565096.3571438966318965, 687240.47098323528189212 7565130.91730566136538982)) | B2: 42 | C2: R-1 | D2: C | E2: F | F2: T | G2: 83.395042 | H2: 0.024 | I2: 398.32245 | J2: 395.86798 | K2: 0 | L2: 0 | O2: 0 | P2: 1.5 | Q2: 0 | R2: 5 | S2: 0 | T2: 1 | U2: 0.5 | V2: 1
A3: MultiLineString ((687647.90818443091120571 7566198.13171269930899143, 687639.36691419442649931 7566249.71658932324498892)) | B3: 43 | C3: R-2 | D3: C | E3: F | F3: T | G3: 52.287214 | H3: 0.024 | I3: 381.20261 | J3: 379.03842 | K3: 0 | L3: 0 | O3: 0 | P3: 1.5 | Q3: 0 | R3: 1 | S3: 0 | T3: 1 | U3: 0.5 | V3: 1
A4: MultiLineString ((687971.95803359965793788 7566446.15060707088559866, 687955.61175127199385315 7566504.66286767460405827)) | B4: 44 | C4: R-3 | D4: C | E4: F | F4: T | G4: 60.752659 | H4: 0.024 | I4: 375.83661 | J4: 379.22119 | K4: 0 | L4: 0 | O4: 0 | P4: 1.5 | Q4: 0 | R4: 2 | S4: 0 | T4: 1 | U4: 0.5 | V4: 1
A5: MultiLineString ((688863.53434349712915719 7566883.80460810009390116, 688881.62753190065268427 7566950.32748960889875889)) | B5: 45 | C5: R-4 | D5: C | E5: F | F5: T | G5: 68.939519 | H5: 0.024 | I5: 364.837 | J5: 364.75 | K5: 0 | L5: 0 | O5: 0 | P5: 1.5 | Q5: 0 | R5: 1 | S5: 0 | T5: 1 | U5: 0.5 | V5: 1
A6: MultiLineString ((689064.92991105315741152 7566962.08014303725212812, 689051.27705024543683976 7567000.71681035682559013)) | B6: 46 | C6: R-5 | D6: C | E6: F | F6: T | G6: 40.977953 | H6: 0.024 | I6: 363.65561 | J6: 363.08899 | K6: 0 | L6: 0 | O6: 0 | P6: 1.5 | Q6: 0 | R6: 1 | S6: 0 | T6: 1 | U6: 0.5 | V6: 1
A7: MultiLineString ((689871.65609456459060311 7567415.68947762716561556, 689840.85410076985135674 7567442.52291673887521029)) | B7: 47 | C7: R-6 | D7: C | E7: F | F7: T | G7: 40.850903 | H7: 0.024 | I7: 353.18802 | J7: 352.41443 | K7: 0 | L7: 0 | O7: 0 | P7: 1.5 | Q7: 0 | R7: 14 | S7: 0 | T7: 1 | U7: 0.5 | V7: 1
A8: MultiLineString ((690763.55012406688183546 7568491.29343010578304529, 690743.11727115733083338 7568514.69833434745669365)) | B8: 48 | C8: R-7 | D8: C | E8: F | F8: T | G8: 31.069133 | H8: 0.024 | I8: 352.16901 | J8: 351.819 | K8: 0 | L8: 0 | O8: 0 | P8: 1.2 | Q8: 0 | R8: 2 | S8: 0 | T8: 1 | U8: 0.5 | V8: 1
A9: MultiLineString ((691279.20103022071998566 7569106.97243891004472971, 691252.82407464657444507 7569121.83269557077437639)) | B9: 49 | C9: R-8 | D9: C | E9: F | F9: T | G9: 30.274924 | H9: 0.024 | I9: 352.68204 | J9: 352.22879 | K9: 0 | L9: 0 | O9: 0 | P9: 1.5 | Q9: 0 | R9: 9 | S9: 0 | T9: 1 | U9: 0.5 | V9: 1
A10: MultiLineString ((691507.72391469345893711 7569388.57430264540016651, 691479.22176939097698778 7569401.46008582692593336)) | B10: 50 | C10: R-9 | D10: C | E10: F | F10: T | G10: 31.279637 | H10: 0.024 | I10: 354.05548 | J10: 353.73798 | K10: 0 | L10: 0 | O10: 0 | P10: 0.9 | Q10: 0 | R10: 3 | S10: 0 | T10: 1 | U10: 0.5 | V10: 1
A11: MultiLineString ((691801.30686036229599267 7569982.24155627377331257, 691774.55839837156236172 7569997.47331935167312622)) | B11: 51 | C11: R-10 | D11: C | E11: F | F11: T | G11: 30.781274 | H11: 0.024 | I11: 349.98645 | J11: 349.86862 | K11: 0 | L11: 0 | O11: 0 | P11: 1.2 | Q11: 0 | R11: 2 | S11: 0 | T11: 1 | U11: 0.5 | V11: 1
A12: MultiLineString ((691909.32235097035299987 7570320.73034003842622042, 691880.06622066791169345 7570339.67716728243976831)) | B12: 52 | C12: R-11 | D12: C | E12: F | F12: T | G12: 34.855465 | H12: 0.024 | I12: 348.3009 | J12: 348.02838 | K12: 0 | L12: 0 | O12: 0 | P12: 1.5 | Q12: 0 | R12: 3 | S12: 0 | T12: 1 | U12: 0.5 | V12: 1
A13: MultiLineString ((692036.69809301919303834 7570740.82406918331980705, 692012.72198079596273601 7570764.29275045823305845)) | B13: 53 | C13: R-12 | D13: C | E13: F | F13: T | G13: 33.550454 | H13: 0.024 | I13: 351.80154 | J13: 351.21353 | K13: 0 | L13: 0 | O13: 0 | P13: 0.9 | Q13: 0 | R13: 2 | S13: 0 | T13: 1 | U13: 0.5 | V13: 1
... A31: MultiLineString ((692189.49452477414160967 7571443.62287487834692001, 692159.25583927519619465 7571463.08685634937137365)) | B31: 78 | C31: R-14b | D31: C | E31: F | F31: T | G31: 35.961433 | H31: 0.024 | I31: 346.563 | J31: 345.325 | K31: 0 | L31: 0 | O31: 0 | P31: 0.9 | Q31: 0 | R31: 1 | S31: 0 | T31: 1 | U31: 0.5 | V31: 1

Sheet PointsTidy -from 1dnwk
B1: ID | C1: {=IF(COUNTA(_xlfn.UNIQUE(_xlfn.ANCHORARRAY(B4)&_xlfn.ANCHORARRAY(C4)))<COUNTA(_xlfn.ANCHORARRAY(C4)),"DUPLICATES","")} -> DUPLICATES
B2: string name | C2: pit name | E2: US_Invert | F2: DS_invert | G2: Number_of | H2: wkt_geom | J2: Width_or_D | K2: Height_or_ | L2: pit centre x | M2: pit centre y | T2: Type | U2: n_nF_Cd
A3: GroupID | B3: ID | C3: ends | D3: vertex_ind | E3: US_Invert | F3: DS_invert | G3: Number_of | H3: wkt_geom | I3: blank | J3: Width_or_D | K3: Height_or_ | L3: xcoord | M3: ycoord | N3: zcoord | O3: MeasureLength | P3: AdjustedLength | Q3: dx | R3: dy | S3: dz | T3: Type | U3: n_nF_Cd | V3: Skew | X3: Ctype | Z3: =COUNTA('1d_nwk-import'!A:A) -> 31 | AA3: Expected bottom excel row number
A4: {=INT((ROW(_xlfn.ANCHORARRAY(B4))-2)/2)} -> 1 | B4: {=_xlfn._xlws.SORT(_xlfn.VSTACK(_xlfn._xlws.FILTER(INDIRECT($AB$5), INDIRECT($AB$5)<>""), _xlfn._xlws.FILTER(INDIRECT($AB$5), INDIRECT($AB$5)<>"")))} -> R-1 | C4: {=_xlfn.ANCHORARRAY(B4)} -> R-1 | D4: {=NOT(MOD(ROW(_xlfn.ANCHORARRAY(B4)),2))*1} -> 1 | E4: {=INDEX('1d_nwk-import'!$A$1:$ZZ$50000,MATCH(_xlfn.ANCHORARRAY($B4),INDIRECT($AC$5),0),INDEX($AA:$AA,MATCH(E$2,$Z:$Z,0)))} -> 398.32245 | F4: {=INDEX('1d_nwk-import'!$A$1:$ZZ$50000,MATCH(_xlfn.ANCHORARRAY($B4),INDIRECT($AC$5),0),INDEX($AA:$AA,MATCH(F$2,$Z:$Z,0)))} -> 395.86798 | G4: {=IFERROR(INDEX('1d_nwk-import'!$A$1:$ZZ$50000,MATCH(_xlfn.ANCHORARRAY($B4),INDIRECT($AC$5),0),INDEX($AA:$AA,MATCH(G$2,$Z:$Z,0))),1)} -> 5 | H4: {=(INDEX('1d_nwk-import'!$A$1:$ZZ$50000,MATCH(_xlfn.ANCHORARRAY($B4),INDIRECT($AC$5),0),INDEX($AA:$AA,MATCH(H$2,$Z:$Z,0))))} -> MultiLineString ((687316.367809071787633 7565096.3571438966318965, 687240.47098323528189212 7565130.91730566136538982)) | I4: {=_xlfn.ANCHORARRAY(J4)} -> 1.5 | J4: {=INDEX('1d_nwk-import'!$A$1:$ZZ$50000,MATCH(_xlfn.ANCHORARRAY($B4),INDIRECT($AC$5),0),INDEX($AA:$AA,MATCH(J$2,$Z:$Z,0)))} -> 1.5 | K4: {=INDEX('1d_nwk-import'!$A$1:$ZZ$50000,MATCH(_xlfn.ANCHORARRAY($B4),INDIRECT($AC$5),0),INDEX($AA:$AA,MATCH(K$2,$Z:$Z,0)))} -> 0 | L4: {=_xlfn.BYROW(_xlfn.ANCHORARRAY(H4), _xlfn.LAMBDA(_xlpm.h, _xlfn.LET( _xlpm.cleanString, SUBSTITUTE(SUBSTITUTE(_xlpm.h, "MultiLineString ((", ""), "))", ""), _xlpm.xmlString, "<t><s>" & SUBSTITUTE(SUBSTITUTE(_xlpm.cleanString, ", ", "</s><s>"), " ", "</s><s>") & "</s></t>", _xlpm.numbers, _xlfn.FILTERXML(_xlpm.xmlString, "//s"), _xlpm.criteria, INDEX(_xlfn.ANCHORARRAY(D4), ROW(_xlpm.h) - ROW(H4) + 1), IF(_xlpm.criteria = 0, INDEX(_xlpm.numbers, 1), INDEX(_xlpm.numbers, 3)) ) ))} -> 687240.47 | M4: {=_xlfn.BYROW(_xlfn.ANCHORARRAY(H4), _xlfn.LAMBDA(_xlpm.h, _xlfn.LET( _xlpm.cleanString, SUBSTITUTE(SUBSTITUTE(_xlpm.h, "MultiLineString ((", ""), "))", ""), _xlpm.xmlString, "<t><s>" & SUBSTITUTE(SUBSTITUTE(_xlpm.cleanString, ", ", "</s><s>"), " ", "</s><s>") & "</s></t>", _xlpm.numbers, _xlfn.FILTERXML(_xlpm.xmlString, "//s"), _xlpm.criteria, INDEX(_xlfn.ANCHORARRAY(D4), ROW(_xlpm.h) - ROW(H4) + 1), IF(_xlpm.criteria = 0, INDEX(_xlpm.numbers, 2), INDEX(_xlpm.numbers, 4)) ) ))} -> 7565130.9 | N4: {=IF(_xlfn.ANCHORARRAY(D4),_xlfn.ANCHORARRAY(E4),_xlfn.ANCHORARRAY(F4))} -> 398.32245 | O4: {=SQRT(_xlfn.ANCHORARRAY(Q4)^2+_xlfn.ANCHORARRAY(R4)^2)} -> 83.395042 | P4: {=_xlfn.ANCHORARRAY(O4)} -> 83.395042 | Q4: {=SUMIFS(L:L,$B:$B,_xlfn.ANCHORARRAY($B4),$D:$D,0)-SUMIFS(L:L,$B:$B,_xlfn.ANCHORARRAY($B4),$D:$D,1)} -> 75.896826 | R4: {=SUMIFS(M:M,$B:$B,_xlfn.ANCHORARRAY($B4),$D:$D,0)-SUMIFS(M:M,$B:$B,_xlfn.ANCHORARRAY($B4),$D:$D,1)} -> -34.560162 | S4: {=_xlfn.ANCHORARRAY(F4)-_xlfn.ANCHORARRAY(E4)} -> -2.4544678 | T4: {=INDEX('1d_nwk-import'!$A$1:$ZZ$50000,MATCH(_xlfn.ANCHORARRAY($B4),INDIRECT($AC$5),0),INDEX($AA:$AA,MATCH(T$2,$Z:$Z,0)))} -> C | U4: {=INDEX('1d_nwk-import'!$A$1:$ZZ$50000,MATCH(_xlfn.ANCHORARRAY($B4),INDIRECT($AC$5),0),INDEX($AA:$AA,MATCH(U$2,$Z:$Z,0)))} -> 0.024 | V4: {=IF(ISBLANK(_xlfn.ANCHORARRAY(B4)),0,90)} -> 90 | X4: {=_xlfn.ANCHORARRAY(T4)} -> C | AB4: 1d_nwk-import | AC4: {=MID(CELL("filename",'1d_nwk-import'!A1),FIND("]",CELL("filename",'1d_nwk-import'!A1))+1,255)} -> 1d_nwk-import
A5: 1 | B5: R-1 | C5: R-1 | D5: 0 | E5: 398.32245 | F5: 395.86798 | G5: 5 | H5: MultiLineString ((687316.367809071787633 7565096.3571438966318965, 687240.47098323528189212 7565130.91730566136538982)) | I5: 1.5 | J5: 1.5 | K5: 0 | L5: 687316.37 | M5: 7565096.4 | N5: 395.86798 | O5: 83.395042 | P5: 83.395042 | Q5: 75.896826 | R5: -34.560162 | S5: -2.4544678 | T5: C | U5: 0.024 | V5: 90 | X5: C | Z5: ID | AA5: =MATCH(Z5,'1d_nwk-import'!$1:$1,0) -> 3 | AB5: =_xlfn.CONCAT(ADDRESS(2,AA5,1,1,AB$4),":",ADDRESS($Z$3,AA5,1,1)) -> '1d_nwk-import'!$C$2:$C$31 | AC5: =_xlfn.CONCAT("'",AC$4,"'!",SUBSTITUTE(ADDRESS(1,AA5,4),"1",""),":",SUBSTITUTE(ADDRESS(1,AA5,4),"1","")) -> '1d_nwk-import'!C:C
A6: 2 | B6: R-10 | C6: R-10 | D6: 1 | E6: 349.98645 | F6: 349.86862 | G6: 2 | H6: MultiLineString ((691801.30686036229599267 7569982.24155627377331257, 691774.55839837156236172 7569997.47331935167312622)) | I6: 1.2 | J6: 1.2 | K6: 0 | L6: 691774.56 | M6: 7569997.5 | N6: 349.98645 | O6: 30.781274 | P6: 30.781274 | Q6: 26.748462 | R6: -15.231763 | S6: -0.11782837 | T6: C | U6: 0.024 | V6: 90 | X6: C | Z6: ID | AA6: =MATCH(Z6,'1d_nwk-import'!$1:$1,0) -> 3 | AB6: =_xlfn.CONCAT(ADDRESS(2,AA6,1,1,AB$4),":",ADDRESS($Z$3,AA6,1,1)) -> '1d_nwk-import'!$C$2:$C$31 | AC6: =_xlfn.CONCAT("'",AC$4,"'!",SUBSTITUTE(ADDRESS(1,AA6,4),"1",""),":",SUBSTITUTE(ADDRESS(1,AA6,4),"1","")) -> '1d_nwk-import'!C:C
A7: 2 | B7: R-10 | C7: R-10 | D7: 0 | E7: 349.98645 | F7: 349.86862 | G7: 2 | H7: MultiLineString ((691801.30686036229599267 7569982.24155627377331257, 691774.55839837156236172 7569997.47331935167312622)) | I7: 1.2 | J7: 1.2 | K7: 0 | L7: 691801.31 | M7: 7569982.2 | N7: 349.86862 | O7: 30.781274 | P7: 30.781274 | Q7: 26.748462 | R7: -15.231763 | S7: -0.11782837 | T7: C | U7: 0.024 | V7: 90 | X7: C | Z7: US_Invert | AA7: =MATCH(Z7,'1d_nwk-import'!$1:$1,0) -> 9 | AC7: =_xlfn.CONCAT("'",AC$4,"'!",SUBSTITUTE(ADDRESS(1,AA7,4),"1",""),":",SUBSTITUTE(ADDRESS(1,AA7,4),"1","")) -> '1d_nwk-import'!I:I
A8: 3 | B8: R-10b | C8: R-10b | D8: 1 | E8: 351.56097 | F8: 351.14426 | G8: 2 | H8: MultiLineString ((691742.79459975729696453 7569821.37927791196852922, 691717.62504003697540611 7569824.07269943132996559)) | I8: 1.2 | J8: 1.2 | K8: 0 | L8: 691717.63 | M8: 7569824.1 | N8: 351.56097 | O8: 25.313262 | P8: 25.313262 | Q8: 25.16956 | R8: -2.6934215 | S8: -0.41671753 | T8: C | U8: 0.024 | V8: 90 | X8: C | Z8: DS_Invert | AA8: =MATCH(Z8,'1d_nwk-import'!$1:$1,0) -> 10 | AC8: =_xlfn.CONCAT("'",AC$4,"'!",SUBSTITUTE(ADDRESS(1,AA8,4),"1",""),":",SUBSTITUTE(ADDRESS(1,AA8,4),"1","")) -> '1d_nwk-import'!J:J
A9: 3 | B9: R-10b | C9: R-10b | D9: 0 | E9: 351.56097 | F9: 351.14426 | G9: 2 | H9: MultiLineString ((691742.79459975729696453 7569821.37927791196852922, 691717.62504003697540611 7569824.07269943132996559)) | I9: 1.2 | J9: 1.2 | K9: 0 | L9: 691742.79 | M9: 7569821.4 | N9: 351.14426 | O9: 25.313262 | P9: 25.313262 | Q9: 25.16956 | R9: -2.6934215 | S9: -0.41671753 | T9: C | U9: 0.024 | V9: 90 | X9: C | Z9: Number_of | AA9: =MATCH(Z9,'1d_nwk-import'!$1:$1,0) -> 18 | AC9: =_xlfn.CONCAT("'",AC$4,"'!",SUBSTITUTE(ADDRESS(1,AA9,4),"1",""),":",SUBSTITUTE(ADDRESS(1,AA9,4),"1","")) -> '1d_nwk-import'!R:R
A10: 4 | B10: R-10c | C10: R-10c | D10: 1 | E10: 353.09366 | F10: 352.65433 | G10: 1 | H10: MultiLineString ((691654.5618258296744898 7569630.88936283066868782, 691636.54376462753862143 7569647.32852176204323769)) | I10: 0.9 | J10: 0.9 | K10: 0 | L10: 691636.54 | M10: 7569647.3 | N10: 353.09366 | O10: 24.3905 | P10: 24.3905 | Q10: 18.018061 | R10: -16.439159 | S10: -0.43933105 | T10: C | U10: 0.024 | V10: 90 | X10: C | Z10: Width_or_D | AA10: =MATCH(Z10,'1d_nwk-import'!$1:$1,0) -> 16 | AC10: =_xlfn.CONCAT("'",AC$4,"'!",SUBSTITUTE(ADDRESS(1,AA10,4),"1",""),":",SUBSTITUTE(ADDRESS(1,AA10,4),"1","")) -> '1d_nwk-import'!P:P
A11: 4 | B11: R-10c | C11: R-10c | D11: 0 | E11: 353.09366 | F11: 352.65433 | G11: 1 | H11: MultiLineString ((691654.5618258296744898 7569630.88936283066868782, 691636.54376462753862143 7569647.32852176204323769)) | I11: 0.9 | J11: 0.9 | K11: 0 | L11: 691654.56 | M11: 7569630.9 | N11: 352.65433 | O11: 24.3905 | P11: 24.3905 | Q11: 18.018061 | R11: -16.439159 | S11: -0.43933105 | T11: C | U11: 0.024 | V11: 90 | X11: C | Z11: width | AA11: =MATCH(Z11,'1d_nwk-import'!$1:$1,0) -> #N/A | AC11: =_xlfn.CONCAT("'",AC$4,"'!",SUBSTITUTE(ADDRESS(1,AA11,4),"1",""),":",SUBSTITUTE(ADDRESS(1,AA11,4),"1","")) -> #N/A
A12: 5 | B12: R-11 | C12: R-11 | D12: 1 | E12: 348.3009 | F12: 348.02838 | G12: 3 | H12: MultiLineString ((691909.32235097035299987 7570320.73034003842622042, 691880.06622066791169345 7570339.67716728243976831)) | I12: 1.5 | J12: 1.5 | K12: 0 | L12: 691880.07 | M12: 7570339.7 | N12: 348.3009 | O12: 34.855465 | P12: 34.855465 | Q12: 29.25613 | R12: -18.946827 | S12: -0.27252197 | T12: C | U12: 0.024 | V12: 90 | X12: C | Z12: pit centre x | AA12: =MATCH(Z12,'1d_nwk-import'!$1:$1,0) -> #N/A | AB12: =_xlfn.CONCAT(ADDRESS(4,AA12,1,1,AB$4),":",ADDRESS($Z$3,AA12,1,1)) -> #N/A | AC12: =_xlfn.CONCAT("'",AC$4,"'!",SUBSTITUTE(ADDRESS(1,AA12,4),"1",""),":",SUBSTITUTE(ADDRESS(1,AA12,4),"1","")) -> #N/A
A13: 5 | B13: R-11 | C13: R-11 | D13: 0 | E13: 348.3009 | F13: 348.02838 | G13: 3 | H13: MultiLineString ((691909.32235097035299987 7570320.73034003842622042, 691880.06622066791169345 7570339.67716728243976831)) | I13: 1.5 | J13: 1.5 | K13: 0 | L13: 691909.32 | M13: 7570320.7 | N13: 348.02838 | O13: 34.855465 | P13: 34.855465 | Q13: 29.25613 | R13: -18.946827 | S13: -0.27252197 | T13: C | U13: 0.024 | V13: 90 | X13: C | Z13: pit centre y | AA13: =MATCH(Z13,'1d_nwk-import'!$1:$1,0) -> #N/A | AB13: =_xlfn.CONCAT(ADDRESS(4,AA13,1,1,AB$4),":",ADDRESS($Z$3,AA13,1,1)) -> #N/A | AC13: =_xlfn.CONCAT("'",AC$4,"'!",SUBSTITUTE(ADDRESS(1,AA13,4),"1",""),":",SUBSTITUTE(ADDRESS(1,AA13,4),"1","")) -> #N/A
A14: 6 | B14: R-12 | C14: R-12 | D14: 1 | E14: 351.80154 | F14: 351.21353 | G14: 2 | H14: MultiLineString ((692036.69809301919303834 7570740.82406918331980705, 692012.72198079596273601 7570764.29275045823305845)) | I14: 0.9 | J14: 0.9 | K14: 0 | L14: 692012.72 | M14: 7570764.3 | N14: 351.80154 | O14: 33.550454 | P14: 33.550454 | Q14: 23.976112 | R14: -23.468681 | S14: -0.5880127 | T14: C | U14: 0.024 | V14: 90 | X14: C | Z14: Type | AA14: =MATCH(Z14,'1d_nwk-import'!$1:$1,0) -> 4 | AC14: =_xlfn.CONCAT("'",AC$4,"'!",SUBSTITUTE(ADDRESS(1,AA14,4),"1",""),":",SUBSTITUTE(ADDRESS(1,AA14,4),"1","")) -> '1d_nwk-import'!D:D
A15: 6 | B15: R-12 | C15: R-12 | D15: 0 | E15: 351.80154 | F15: 351.21353 | G15: 2 | H15: MultiLineString ((692036.69809301919303834 7570740.82406918331980705, 692012.72198079596273601 7570764.29275045823305845)) | I15: 0.9 | J15: 0.9 | K15: 0 | L15: 692036.7 | M15: 7570740.8 | N15: 351.21353 | O15: 33.550454 | P15: 33.550454 | Q15: 23.976112 | R15: -23.468681 | S15: -0.5880127 | T15: C | U15: 0.024 | V15: 90 | X15: C | Z15: Height_or_ | AA15: =MATCH(Z15,'1d_nwk-import'!$1:$1,0) -> 17 | AC15: =_xlfn.CONCAT("'",AC$4,"'!",SUBSTITUTE(ADDRESS(1,AA15,4),"1",""),":",SUBSTITUTE(ADDRESS(1,AA15,4),"1","")) -> '1d_nwk-import'!Q:Q
A16: 7 | B16: R-13 | C16: R-13 | D16: 1 | E16: 344.2049 | F16: 343.79401 | G16: 4 | H16: MultiLineString ((692161.01794817426707596 7571146.96061041299253702, 692109.38757610891479999 7571160.85003517102450132)) | I16: 1.5 | J16: 1.5 | K16: 0 | L16: 692109.39 | M16: 7571160.9 | N16: 344.2049 | O16: 53.465984 | P16: 53.465984 | Q16: 51.630372 | R16: -13.889425 | S16: -0.41088867 | T16: C | U16: 0.024 | V16: 90 | X16: C | Z16: n_nF_Cd | AA16: =MATCH(Z16,'1d_nwk-import'!$1:$1,0) -> 8 | AC16: =_xlfn.CONCAT("'",AC$4,"'!",SUBSTITUTE(ADDRESS(1,AA16,4),"1",""),":",SUBSTITUTE(ADDRESS(1,AA16,4),"1","")) -> '1d_nwk-import'!H:H
A17: 7 | B17: R-13 | C17: R-13 | D17: 0 | E17: 344.2049 | F17: 343.79401 | G17: 4 | H17: MultiLineString ((692161.01794817426707596 7571146.96061041299253702, 692109.38757610891479999 7571160.85003517102450132)) | I17: 1.5 | J17: 1.5 | K17: 0 | L17: 692161.02 | M17: 7571147 | N17: 343.79401 | O17: 53.465984 | P17: 53.465984 | Q17: 51.630372 | R17: -13.889425 | S17: -0.41088867 | T17: C | U17: 0.024 | V17: 90 | X17: C | Z17: wkt_geom | AA17: =MATCH(Z17,'1d_nwk-import'!$1:$1,0) -> 1 | AC17: =_xlfn.CONCAT("'",AC$4,"'!",SUBSTITUTE(ADDRESS(1,AA17,4),"1",""),":",SUBSTITUTE(ADDRESS(1,AA17,4),"1","")) -> '1d_nwk-import'!A:A
A18: 8 | B18: R-14 | C18: R-14 | D18: 1 | E18: 342.7135 | F18: 342.29199 | G18: 4 | H18: MultiLineString ((692208.38501628290396184 7571615.61595487501472235, 692159.34616929991170764 7571613.57266958430409431)) | I18: 1.5 | J18: 1.5 | K18: 0 | L18: 692159.35 | M18: 7571613.6 | N18: 342.7135 | O18: 49.081397 | P18: 49.081397 | Q18: 49.038847 | R18: 2.0432853 | S18: -0.42150879 | T18: C | U18: 0.024 | V18: 90 | X18: C
A19: 8 | B19: R-14 | C19: R-14 | D19: 0 | E19: 342.7135 | F19: 342.29199 | G19: 4 | H19: MultiLineString ((692208.38501628290396184 7571615.61595487501472235, 692159.34616929991170764 7571613.57266958430409431)) | I19: 1.5 | J19: 1.5 | K19: 0 | L19: 692208.39 | M19: 7571615.6 | N19: 342.29199 | O19: 49.081397 | P19: 49.081397 | Q19: 49.038847 | R19: 2.0432853 | S19: -0.42150879 | T19: C | U19: 0.024 | V19: 90 | X19: C
A20: 9 | B20: R-14b | C20: R-14b | D20: 1 | E20: 346.563 | F20: 345.325 | G20: 1 | H20: MultiLineString ((692189.49452477414160967 7571443.62287487834692001, 692159.25583927519619465 7571463.08685634937137365)) | I20: 0.9 | J20: 0.9 | K20: 0 | L20: 692159.26 | M20: 7571463.1 | N20: 346.563 | O20: 35.961433 | P20: 35.961433 | Q20: 30.238685 | R20: -19.463981 | S20: -1.238 | T20: C | U20: 0.024 | V20: 90 | X20: C | Z20: expected | AA20: =COUNTA(_xlfn.ANCHORARRAY(B4))/2 -> 30
A21: 9 | B21: R-14b | C21: R-14b | D21: 0 | E21: 346.563 | F21: 345.325 | G21: 1 | H21: MultiLineString ((692189.49452477414160967 7571443.62287487834692001, 692159.25583927519619465 7571463.08685634937137365)) | I21: 0.9 | J21: 0.9 | K21: 0 | L21: 692189.49 | M21: 7571443.6 | N21: 345.325 | O21: 35.961433 | P21: 35.961433 | Q21: 30.238685 | R21: -19.463981 | S21: -1.238 | T21: C | U21: 0.024 | V21: 90 | X21: C
A22: 10 | B22: R-15 | C22: R-15 | D22: 1 | E22: 344.97507 | F22: 344.4899 | G22: 2 | H22: MultiLineString ((692207.45625024160835892 7571762.91824903339147568, 692168.81958292168565094 7571777.40699927881360054)) | I22: 1.5 | J22: 1.5 | K22: 0 | L22: 692168.82 | M22: 7571777.4 | N22: 344.97507 | O22: 41.263979 | P22: 41.263979 | Q22: 38.636667 | R22: -14.48875 | S22: -0.48516846 | T22: C | U22: 0.024 | V22: 90 | X22: C
A23: 10 | B23: R-15 | C23: R-15 | D23: 0 | E23: 344.97507 | F23: 344.4899 | G23: 2 | H23: MultiLineString ((692207.45625024160835892 7571762.91824903339147568, 692168.81958292168565094 7571777.40699927881360054)) | I23: 1.5 | J23: 1.5 | K23: 0 | L23: 692207.46 | M23: 7571762.9 | N23: 344.4899 | O23: 41.263979 | P23: 41.263979 | Q23: 38.636667 | R23: -14.48875 | S23: -0.48516846 | T23: C | U23: 0.024 | V23: 90 | X23: C
A24: 11 | B24: R-16 | C24: R-16 | D24: 1 | E24: 347.94794 | F24: 347.10492 | G24: 1 | H24: MultiLineString ((692226.58883069327566773 7572259.15794492140412331, 692181.91518410469871014 7572253.02808904834091663)) | I24: 1.2 | J24: 1.2 | K24: 0 | L24: 692181.92 | M24: 7572253 | N24: 347.94794 | O24: 45.092237 | P24: 45.092237 | Q24: 44.673647 | R24: 6.1298559 | S24: -0.84301758 | T24: C | U24: 0.024 | V24: 90 | X24: C
A25: 11 | B25: R-16 | C25: R-16 | D25: 0 | E25: 347.94794 | F25: 347.10492 | G25: 1 | H25: MultiLineString ((692226.58883069327566773 7572259.15794492140412331, 692181.91518410469871014 7572253.02808904834091663)) | I25: 1.2 | J25: 1.2 | K25: 0 | L25: 692226.59 | M25: 7572259.2 | N25: 347.10492 | O25: 45.092237 | P25: 45.092237 | Q25: 44.673647 | R25: 6.1298559 | S25: -0.84301758 | T25: C | U25: 0.024 | V25: 90 | X25: C
A26: 12 | B26: R-17 | C26: R-17 | D26: 1 | E26: 337.30045 | F26: 337.15353 | G26: 2 | H26: MultiLineString ((692464.0743074647616595 7573334.20463777799159288, 692436.02557301614433527 7573348.69338802248239517)) | I26: 1.5 | J26: 1.5 | K26: 0 | L26: 692436.03 | M26: 7573348.7 | N26: 337.30045 | O26: 31.569849 | P26: 31.569849 | Q26: 28.048734 | R26: -14.48875 | S26: -0.14691162 | T26: C | U26: 0.024 | V26: 90 | X26: C
A27: 12 | B27: R-17 | C27: R-17 | D27: 0 | E27: 337.30045 | F27: 337.15353 | G27: 2 | H27: MultiLineString ((692464.0743074647616595 7573334.20463777799159288, 692436.02557301614433527 7573348.69338802248239517)) | I27: 1.5 | J27: 1.5 | K27: 0 | L27: 692464.07 | M27: 7573334.2 | N27: 337.15353 | O27: 31.569849 | P27: 31.569849 | Q27: 28.048734 | R27: -14.48875 | S27: -0.14691162 | T27: C | U27: 0.024 | V27: 90 | X27: C
A28: 13 | B28: R-17b | C28: R-17b | D28: 1 | E28: 337.62054 | F28: 336.73544 | G28: 1 | H28: MultiLineString ((692507.26192838733550161 7573519.77209283597767353, 692464.7244436937617138 7573513.27073054667562246)) | I28: 0.9 | J28: 0.9 | K28: 0 | L28: 692464.72 | M28: 7573513.3 | N28: 337.62054 | O28: 43.031446 | P28: 43.031446 | Q28: 42.537485 | R28: 6.5013623 | S28: -0.88510132 | T28: C | U28: 0.024 | V28: 90 | X28: C
A29: 13 | B29: R-17b | C29: R-17b | D29: 0 | E29: 337.62054 | F29: 336.73544 | G29: 1 | H29: MultiLineString ((692507.26192838733550161 7573519.77209283597767353, 692464.7244436937617138 7573513.27073054667562246)) | I29: 0.9 | J29: 0.9 | K29: 0 | L29: 692507.26 | M29: 7573519.8 | N29: 336.73544 | O29: 43.031446 | P29: 43.031446 | Q29: 42.537485 | R29: 6.5013623 | S29: -0.88510132 | T29: C | U29: 0.024 | V29: 90 | X29: C
A30: 14 | B30: R-18 | C30: R-18 | D30: 1 | E30: 326.11298 | F30: 326.04398 | G30: 5 | H30: MultiLineString ((693238.80200534139294177 7574681.5327999098226428, 693222.05678410606924444 7574705.88948534335941076)) | I30: 1.2 | J30: 1.2 | K30: 0 | L30: 693222.06 | M30: 7574705.9 | N30: 326.11298 | O30: 29.55758 | P30: 29.55758 | Q30: 16.745221 | R30: -24.356685 | S30: -0.069000244 | T30: C | U30: 0.024 | V30: 90 | X30: C
A31: 14 | B31: R-18 | C31: R-18 | D31: 0 | E31: 326.11298 | F31: 326.04398 | G31: 5 | H31: MultiLineString ((693238.80200534139294177 7574681.5327999098226428, 693222.05678410606924444 7574705.88948534335941076)) | I31: 1.2 | J31: 1.2 | K31: 0 | L31: 693238.8 | M31: 7574681.5 | N31: 326.04398 | O31: 29.55758 | P31: 29.55758 | Q31: 16.745221 | R31: -24.356685 | S31: -0.069000244 | T31: C | U31: 0.024 | V31: 90 | X31: C
A32: 15 | B32: R-18b | C32: R-18b | D32: 1 | E32: 328.62906 | F32: 328.22598 | G32: 1 | H32: MultiLineString ((692940.16620135749690235 7574340.58407421596348286, 692998.12120233732275665 7574357.67336937598884106)) | I32: 1.2 | J32: 1.2 | K32: 0 | L32: 692998.12 | M32: 7574357.7 | N32: 328.62906 | O32: 60.422067 | P32: 60.422067 | Q32: -57.955001 | R32: -17.089295 | S32: -0.40307617 | T32: C | U32: 0.024 | V32: 90 | X32: C
... A63: 30 | B63: R-9 | C63: R-9 | D63: 0 | E63: 354.05548 | F63: 353.73798 | G63: 3 | H63: MultiLineString ((691507.72391469345893711 7569388.57430264540016651, 691479.22176939097698778 7569401.46008582692593336)) | I63: 0.9 | J63: 0.9 | K63: 0 | L63: 691507.72 | M63: 7569388.6 | N63: 353.73798 | O63: 31.279637 | P63: 31.279637 | Q63: 28.502145 | R63: -12.885783 | S63: -0.31750488 | T63: C | U63: 0.024 | V63: 90 | X63: C
L96: {=_xlfn.LET( _xlpm.cleanString, SUBSTITUTE(SUBSTITUTE(H4, "MultiLineString ((", ""), "))", ""), _xlpm.xmlString, "<t><s>" & SUBSTITUTE(SUBSTITUTE(_xlpm.cleanString, ", ", "</s><s>"), " ", "</s><s>") & "</s></t>", _xlpm.numbers, _xlfn.FILTERXML(_xlpm.xmlString, "//s"),_xlpm.numbers)} -> 687316.37
L97: 7565096.4
L98: 687240.47
L99: 7565130.9

Sheet PointsTidy - 12D
C1: {=IF(COUNTA(_xlfn.UNIQUE(_xlfn.ANCHORARRAY(B4)&_xlfn.ANCHORARRAY(C4)))<COUNTA(_xlfn.ANCHORARRAY(C4)),"DUPLICATES","")} | W1: CHANGE CULVERT NAMES HERE (IF DESIRED) | AM1: raw name | AN1: adj name
B2: string name | C2: pit name | E2: invert us | F2: invert ds | G2: number of pipes | H2: diameter | I2: width | K2: width | L2: pit centre x | M2: pit centre y | T2: pipe type | AM2: {=_xlfn._xlws.SORT(_xlfn.UNIQUE(_xlfn.ANCHORARRAY(B4)))} -> channel nth | AN2: ChinN2
A3: GroupID | B3: ID | C3: ends | D3: vertex_ind | E3: US_Invert | F3: DS_invert | G3: Number_of | H3: raw_diam | I3: raw_width | J3: Width_or_D | K3: Height_or_ | L3: xcoord | M3: ycoord | N3: zcoord | O3: MeasureLength | P3: AdjustedLength | Q3: dx | R3: dy | S3: dz | T3: Type | U3: Mannings | V3: Skew | W3: NewName | X3: Ctype | Z3: =COUNTA('12D-Culverts.rpt'!A:A) -> 5 | AA3: Expected bottom excel row number | AN3: chinH2
A4: {=INT((ROW(_xlfn.ANCHORARRAY(B4))-2)/2)} -> 1 | B4: {=_xlfn._xlws.FILTER(INDIRECT($AB$5),INDIRECT($AB$5)<>"")} -> channel nth | C4: {=_xlfn._xlws.FILTER(INDIRECT($AB$6),INDIRECT($AB$6)<>"")} -> inlet | D4: {=NOT(MOD(ROW(_xlfn.ANCHORARRAY(B4)),2))*1} -> 1 | E4: {=INDEX('12D-Culverts.rpt'!$A$1:$ZZ$50000,MATCH(_xlfn.ANCHORARRAY($B4),INDIRECT($AC$5),0),INDEX($AA:$AA,MATCH(E$2,$Z:$Z,0)))} -> 147.5 | F4: {=INDEX('12D-Culverts.rpt'!$A$1:$ZZ$50000,MATCH(_xlfn.ANCHORARRAY($B4),INDIRECT($AC$5),0),INDEX($AA:$AA,MATCH(F$2,$Z:$Z,0)))} -> 147.4 | G4: {=IFERROR(INDEX('12D-Culverts.rpt'!$A$1:$ZZ$50000,MATCH(_xlfn.ANCHORARRAY($B4),INDIRECT($AC$5),0),INDEX($AA:$AA,MATCH(G$2,$Z:$Z,0))),1)} -> 2 | H4: {=INDEX('12D-Culverts.rpt'!$A$1:$ZZ$50000,MATCH(_xlfn.ANCHORARRAY($B4),INDIRECT($AC$5),0),INDEX($AA:$AA,MATCH(H$2,$Z:$Z,0)))} -> 0.6 | I4: {=IFERROR(INDEX('12D-Culverts.rpt'!$A$1:$ZZ$50000,MATCH(_xlfn.ANCHORARRAY($B4),INDIRECT($AC$5),0),INDEX($AA:$AA,MATCH(I$2,$Z:$Z,0))),)} -> 1.2 | J4: {=IF(_xlfn.ANCHORARRAY(I4),_xlfn.ANCHORARRAY(I4),_xlfn.ANCHORARRAY(H4))} -> 1.2 | K4: {=IF(_xlfn.ANCHORARRAY(I4),_xlfn.ANCHORARRAY(H4),0)} -> 0.6 | L4: {=SUMIFS(INDIRECT(AB12),INDIRECT(AB5),_xlfn.ANCHORARRAY(B4),INDIRECT(AB6),_xlfn.ANCHORARRAY(C4))} -> 688661.53 | M4: {=SUMIFS(INDIRECT(AB13),INDIRECT(AB5),_xlfn.ANCHORARRAY(B4),INDIRECT(AB6),_xlfn.ANCHORARRAY(C4))} -> 7671744.2 | N4: {=IF(_xlfn.ANCHORARRAY(D4),_xlfn.ANCHORARRAY(E4),_xlfn.ANCHORARRAY(F4))} -> 147.5 | O4: {=SQRT(_xlfn.ANCHORARRAY(Q4)^2+_xlfn.ANCHORARRAY(R4)^2)} -> 26.780951 | P4: {=_xlfn.ANCHORARRAY(O4)} -> 26.780951 | Q4: {=SUMIFS(L:L,$B:$B,_xlfn.ANCHORARRAY($B4),$D:$D,0)-SUMIFS(L:L,$B:$B,_xlfn.ANCHORARRAY($B4),$D:$D,1)} -> -26.023822 | R4: {=SUMIFS(M:M,$B:$B,_xlfn.ANCHORARRAY($B4),$D:$D,0)-SUMIFS(M:M,$B:$B,_xlfn.ANCHORARRAY($B4),$D:$D,1)} -> -6.322974 | S4: {=_xlfn.ANCHORARRAY(F4)-_xlfn.ANCHORARRAY(E4)} -> -0.1 | T4: {=INDEX(Table14[pipet],MATCH(_xlfn.ANCHORARRAY(X4),Table14[Type],0))} -> R | U4: {=INDEX(Table14[mannings],MATCH(_xlfn.ANCHORARRAY(X4),Table14[Type],0))} -> 0.012 | V4: {=INDEX(ProcessAngle!J:J,MATCH(_xlfn.ANCHORARRAY('PointsTidy - 12D'!B4),ProcessAngle!L:L,0))} -> 90 | W4: {=IF(_xlfn.ANCHORARRAY(A4),VLOOKUP(_xlfn.ANCHORARRAY(B4),AM:AN,2,0))} -> ChinN2 | X4: {=INDEX('12D-Culverts.rpt'!$A$1:$ZZ$50000,MATCH(_xlfn.ANCHORARRAY($B4),INDIRECT($AC$5),0),INDEX($AA:$AA,MATCH(T$2,$Z:$Z,0)))} -> BC | AB4: =AC4 -> 12D-Culverts.rpt | AC4: {=MID(CELL("filename",'12D-Culverts.rpt'!A1),FIND("]",CELL("filename",'12D-Culverts.rpt'!A1))+1,255)} -> 12D-Culverts.rpt | AN4: ChinH1
A5: 1 | B5: channel nth | C5: outlet | D5: 0 | E5: 147.5 | F5: 147.4 | G5: 2 | H5: 0.6 | I5: 1.2 | J5: 1.2 | K5: 0.6 | L5: 688635.5 | M5: 7671737.9 | N5: 147.4 | O5: 26.780951 | P5: 26.780951 | Q5: -26.023822 | R5: -6.322974 | S5: -0.1 | T5: R | U5: 0.012 | V5: 90 | W5: ChinN2 | X5: BC | Z5: string name | AA5: =MATCH(Z5,'12D-Culverts.rpt'!$2:$2,0) -> 3 | AB5: =_xlfn.CONCAT(ADDRESS(4,AA5,1,1,AB$4),":",ADDRESS($Z$3,AA5,1,1)) -> '12D-Culverts.rpt'!$C$4:$C$5 | AC5: =_xlfn.CONCAT("'",AC$4,"'!",SUBSTITUTE(ADDRESS(1,AA5,4),"1",""),":",SUBSTITUTE(ADDRESS(1,AA5,4),"1","")) -> '12D-Culverts.rpt'!C:C | AG5: These are #N/A error if not found on the import sheet | AN5: ChinL
Z6: pit name | AA6: =MATCH(Z6,'12D-Culverts.rpt'!$2:$2,0) -> 4 | AB6: =_xlfn.CONCAT(ADDRESS(4,AA6,1,1,AB$4),":",ADDRESS($Z$3,AA6,1,1)) -> '12D-Culverts.rpt'!$D$4:$D$5 | AC6: =_xlfn.CONCAT("'",AC$4,"'!",SUBSTITUTE(ADDRESS(1,AA6,4),"1",""),":",SUBSTITUTE(ADDRESS(1,AA6,4),"1","")) -> '12D-Culverts.rpt'!D:D | AN6: gillam
Z7: invert us | AA7: =MATCH(Z7,'12D-Culverts.rpt'!$2:$2,0) -> 13 | AC7: =_xlfn.CONCAT("'",AC$4,"'!",SUBSTITUTE(ADDRESS(1,AA7,4),"1",""),":",SUBSTITUTE(ADDRESS(1,AA7,4),"1","")) -> '12D-Culverts.rpt'!M:M | AG7: The sheet expects 3 rows of titles, then the data | AN7: turner1
Z8: invert ds | AA8: =MATCH(Z8,'12D-Culverts.rpt'!$2:$2,0) -> 14 | AC8: =_xlfn.CONCAT("'",AC$4,"'!",SUBSTITUTE(ADDRESS(1,AA8,4),"1",""),":",SUBSTITUTE(ADDRESS(1,AA8,4),"1","")) -> '12D-Culverts.rpt'!N:N | AG8: the titles in row T need to be on row 2 of the import | AN8: turner2
Z9: number of pipes | AA9: =MATCH(Z9,'12D-Culverts.rpt'!$2:$2,0) -> 17 | AC9: =_xlfn.CONCAT("'",AC$4,"'!",SUBSTITUTE(ADDRESS(1,AA9,4),"1",""),":",SUBSTITUTE(ADDRESS(1,AA9,4),"1","")) -> '12D-Culverts.rpt'!Q:Q | AN9: turnerW
Z10: diameter | AA10: =MATCH(Z10,'12D-Culverts.rpt'!$2:$2,0) -> 15 | AC10: =_xlfn.CONCAT("'",AC$4,"'!",SUBSTITUTE(ADDRESS(1,AA10,4),"1",""),":",SUBSTITUTE(ADDRESS(1,AA10,4),"1","")) -> '12D-Culverts.rpt'!O:O | AG10: Type | AH10: mannings | AI10: pipet | AN10: ChinN1
Z11: width | AA11: =MATCH(Z11,'12D-Culverts.rpt'!$2:$2,0) -> 16 | AC11: =_xlfn.CONCAT("'",AC$4,"'!",SUBSTITUTE(ADDRESS(1,AA11,4),"1",""),":",SUBSTITUTE(ADDRESS(1,AA11,4),"1","")) -> '12D-Culverts.rpt'!P:P | AG11: CSP | AH11: 0.024 | AI11: C
Z12: pit centre x | AA12: =MATCH(Z12,'12D-Culverts.rpt'!$2:$2,0) -> 7 | AB12: =_xlfn.CONCAT(ADDRESS(4,AA12,1,1,AB$4),":",ADDRESS($Z$3,AA12,1,1)) -> '12D-Culverts.rpt'!$G$4:$G$5 | AC12: =_xlfn.CONCAT("'",AC$4,"'!",SUBSTITUTE(ADDRESS(1,AA12,4),"1",""),":",SUBSTITUTE(ADDRESS(1,AA12,4),"1","")) -> '12D-Culverts.rpt'!G:G | AG12: BC | AH12: 0.012 | AI12: R
Z13: pit centre y | AA13: =MATCH(Z13,'12D-Culverts.rpt'!$2:$2,0) -> 8 | AB13: =_xlfn.CONCAT(ADDRESS(4,AA13,1,1,AB$4),":",ADDRESS($Z$3,AA13,1,1)) -> '12D-Culverts.rpt'!$H$4:$H$5 | AC13: =_xlfn.CONCAT("'",AC$4,"'!",SUBSTITUTE(ADDRESS(1,AA13,4),"1",""),":",SUBSTITUTE(ADDRESS(1,AA13,4),"1","")) -> '12D-Culverts.rpt'!H:H
Z14: pipe type | AA14: =MATCH(Z14,'12D-Culverts.rpt'!$2:$2,0) -> 12 | AC14: =_xlfn.CONCAT("'",AC$4,"'!",SUBSTITUTE(ADDRESS(1,AA14,4),"1",""),":",SUBSTITUTE(ADDRESS(1,AA14,4),"1","")) -> '12D-Culverts.rpt'!L:L
Z16: unique | AA16: =COUNTA(_xlfn.UNIQUE(_xlfn.ANCHORARRAY(W4))) -> 1
Z17: expected | AA17: =COUNTA(_xlfn.ANCHORARRAY(B4))/2 -> 1
AE19: =ADDRESS(1,AA5,,,"BGER-12D.rpt") -> 'BGER-12D.rpt'!$C$1

Sheet ProcessAngle
A1: ° | B1: ' | C1: " | D1: > | E1: Degrees | F1: Minutes | G1: Seconds | H1: Decimal | I1: From90 | J1: Skew | K1: trim1 | L1: Culvert | M1: Raw Data | O1: Can this go negative? Probably, and should work
A2: {=SEARCH(A$1,_xlfn.ANCHORARRAY($M2))} -> #VALUE! | B2: {=SEARCH(B$1,_xlfn.ANCHORARRAY($M2))} -> #VALUE! | C2: {=SEARCH(C$1,_xlfn.ANCHORARRAY($M2))} -> #VALUE! | D2: {=SEARCH(D$1,_xlfn.ANCHORARRAY($M2))} -> #VALUE! | E2: {=VALUE(MID(_xlfn.ANCHORARRAY($M2),_xlfn.ANCHORARRAY(A2)-3,3))} -> #VALUE! | F2: {=VALUE(MID(_xlfn.ANCHORARRAY($M2),_xlfn.ANCHORARRAY(B2)-2,2))} -> #VALUE! | G2: {=VALUE(MID(_xlfn.ANCHORARRAY($M2),_xlfn.ANCHORARRAY(C2)-2,2))} -> #VALUE! | H2: {=_xlfn.ANCHORARRAY(E2)+_xlfn.ANCHORARRAY(F2)/60+_xlfn.ANCHORARRAY(G2)/60/60} -> #VALUE! | I2: {=90+_xlfn.ANCHORARRAY(H2)} -> #VALUE! | J2: {=_xlfn.ANCHORARRAY(I2)} -> #VALUE! | K2: {=RIGHT(_xlfn.ANCHORARRAY(M2),LEN(_xlfn.ANCHORARRAY(M2))-_xlfn.ANCHORARRAY(D2))} -> #VALUE! | L2: {=LEFT(_xlfn.ANCHORARRAY(K2),LEN(_xlfn.ANCHORARRAY(K2))-1)} -> #VALUE! | M2: {=_xlfn._xlws.FILTER('12D-Road.rpt'!A:A,'12D-Road.rpt'!A:A<>"")} -> -----------------------------------------------------------------------------------------------------------
A3: #VALUE! | B3: #VALUE! | C3: 21 | D3: #VALUE! | E3: #VALUE! | F3: #VALUE! | G3: #VALUE! | H3: #VALUE! | I3: #VALUE! | J3: #VALUE! | K3: #VALUE! | L3: #VALUE! | M3: Road centre line "north chinnamon floodway"
A4: #VALUE! | B4: #VALUE! | C4: #VALUE! | D4: #VALUE! | E4: #VALUE! | F4: #VALUE! | G4: #VALUE! | H4: #VALUE! | I4: #VALUE! | J4: #VALUE! | K4: #VALUE! | L4: #VALUE! | M4: -----------------------------------------------------------------------------------------------------------
A5: #VALUE! | B5: #VALUE! | C5: #VALUE! | D5: #VALUE! | E5: #VALUE! | F5: #VALUE! | G5: #VALUE! | H5: #VALUE! | I5: #VALUE! | J5: #VALUE! | K5: #VALUE! | L5: #VALUE! | M5: Crossing Centreline String
A6: #VALUE! | B6: #VALUE! | C6: #VALUE! | D6: #VALUE! | E6: #VALUE! | F6: #VALUE! | G6: #VALUE! | H6: #VALUE! | I6: #VALUE! | J6: #VALUE! | K6: #VALUE! | L6: #VALUE! | M6: Easting Northing Angle Chainage Height Chainage Height Slope% Name
A7: #VALUE! | B7: #VALUE! | C7: #VALUE! | D7: #VALUE! | E7: #VALUE! | F7: #VALUE! | G7: #VALUE! | H7: #VALUE! | I7: #VALUE! | J7: #VALUE! | K7: #VALUE! | L7: #VALUE! | M7: -----------------------------------------------------------------------------------------------------------
A8: 30 | B8: 33 | C8: 36 | D8: 110 | E8: 0 | F8: 0 | G8: 0 | H8: 0 | I8: 90 | J8: 90 | K8: channel nth" | L8: channel nth | M8: 688648.485 7671741.060 0° 0' 0" 445.000 149.001 13.421 147.450 -0.38 "CULVERTS FW->channel nth"
A9: 30 | B9: 33 | C9: 36 | D9: 110 | E9: 0 | F9: 0 | G9: 0 | H9: 0 | I9: 90 | J9: 90 | K9: main channel sth" | L9: main channel sth | M9: 688680.358 7671609.876 0° 0' 0" 310.000 149.000 16.194 146.802 -0.61 "CULVERTS FW->main channel sth"
A10: #VALUE! | B10: #VALUE! | C10: #VALUE! | D10: #VALUE! | E10: #VALUE! | F10: #VALUE! | G10: #VALUE! | H10: #VALUE! | I10: #VALUE! | J10: #VALUE! | K10: #VALUE! | L10: #VALUE! | M10: -----------------------------------------------------------------------------------------------------------
A11: #VALUE! | B11: #VALUE! | C11: #VALUE! | D11: #VALUE! | E11: #VALUE! | F11: #VALUE! | G11: #VALUE! | H11: #VALUE! | I11: #VALUE! | J11: #VALUE! | K11: #VALUE! | L11: #VALUE! | M11: -----------------------------------------------------------------------------------------------------------
A12: #VALUE! | B12: #VALUE! | C12: 21 | D12: #VALUE! | E12: #VALUE! | F12: #VALUE! | G12: #VALUE! | H12: #VALUE! | I12: #VALUE! | J12: #VALUE! | K12: #VALUE! | L12: #VALUE! | M12: Road centre line "Chinnamon"
A13: #VALUE! | B13: #VALUE! | C13: #VALUE! | D13: #VALUE! | E13: #VALUE! | F13: #VALUE! | G13: #VALUE! | H13: #VALUE! | I13: #VALUE! | J13: #VALUE! | K13: #VALUE! | L13: #VALUE! | M13: -----------------------------------------------------------------------------------------------------------
A14: #VALUE! | B14: #VALUE! | C14: #VALUE! | D14: #VALUE! | E14: #VALUE! | F14: #VALUE! | G14: #VALUE! | H14: #VALUE! | I14: #VALUE! | J14: #VALUE! | K14: #VALUE! | L14: #VALUE! | M14: Crossing Centreline String
A15: #VALUE! | B15: #VALUE! | C15: #VALUE! | D15: #VALUE! | E15: #VALUE! | F15: #VALUE! | G15: #VALUE! | H15: #VALUE! | I15: #VALUE! | J15: #VALUE! | K15: #VALUE! | L15: #VALUE! | M15: Easting Northing Angle Chainage Height Chainage Height Slope% Name
A16: #VALUE! | B16: #VALUE! | C16: #VALUE! | D16: #VALUE! | E16: #VALUE! | F16: #VALUE! | G16: #VALUE! | H16: #VALUE! | I16: #VALUE! | J16: #VALUE! | K16: #VALUE! | L16: #VALUE! | M16: -----------------------------------------------------------------------------------------------------------
A17: 30 | B17: 33 | C17: 36 | D17: 110 | E17: 8 | F17: 6 | G17: 51 | H17: 8.1141667 | I17: 98.114167 | J17: 98.114167 | K17: culvert Chinnamon Crk" | L17: culvert Chinnamon Crk | M17: 687903.291 7671196.904 8° 6'51" 14747.731 149.604 16.072 146.955 -0.28 "CULVERTS FW->culvert Chinnamon Crk"
A18: 30 | B18: 33 | C18: 36 | D18: 110 | E18: 0 | F18: 0 | G18: 0 | H18: 0 | I18: 90 | J18: 90 | K18: culvert Chinnamon Crk 001" | L18: culvert Chinnamon Crk 001 | M18: 687697.042 7671144.787 0° 0' 0" 14535.000 149.633 22.911 146.448 -0.23 "CULVERTS FW->culvert Chinnamon Crk 001"
A19: #VALUE! | B19: #VALUE! | C19: #VALUE! | D19: #VALUE! | E19: #VALUE! | F19: #VALUE! | G19: #VALUE! | H19: #VALUE! | I19: #VALUE! | J19: #VALUE! | K19: #VALUE! | L19: #VALUE! | M19: -----------------------------------------------------------------------------------------------------------
A20: #VALUE! | B20: #VALUE! | C20: #VALUE! | D20: #VALUE! | E20: #VALUE! | F20: #VALUE! | G20: #VALUE! | H20: #VALUE! | I20: #VALUE! | J20: #VALUE! | K20: #VALUE! | L20: #VALUE! | M20: -----------------------------------------------------------------------------------------------------------
A21: #VALUE! | B21: #VALUE! | C21: 21 | D21: #VALUE! | E21: #VALUE! | F21: #VALUE! | G21: #VALUE! | H21: #VALUE! | I21: #VALUE! | J21: #VALUE! | K21: #VALUE! | L21: #VALUE! | M21: Road centre line "Chinnamon low level option"
A22: #VALUE! | B22: #VALUE! | C22: #VALUE! | D22: #VALUE! | E22: #VALUE! | F22: #VALUE! | G22: #VALUE! | H22: #VALUE! | I22: #VALUE! | J22: #VALUE! | K22: #VALUE! | L22: #VALUE! | M22: -----------------------------------------------------------------------------------------------------------
A23: #VALUE! | B23: #VALUE! | C23: #VALUE! | D23: #VALUE! | E23: #VALUE! | F23: #VALUE! | G23: #VALUE! | H23: #VALUE! | I23: #VALUE! | J23: #VALUE! | K23: #VALUE! | L23: #VALUE! | M23: Crossing Centreline String
A24: #VALUE! | B24: #VALUE! | C24: #VALUE! | D24: #VALUE! | E24: #VALUE! | F24: #VALUE! | G24: #VALUE! | H24: #VALUE! | I24: #VALUE! | J24: #VALUE! | K24: #VALUE! | L24: #VALUE! | M24: Easting Northing Angle Chainage Height Chainage Height Slope% Name
A25: #VALUE! | B25: #VALUE! | C25: #VALUE! | D25: #VALUE! | E25: #VALUE! | F25: #VALUE! | G25: #VALUE! | H25: #VALUE! | I25: #VALUE! | J25: #VALUE! | K25: #VALUE! | L25: #VALUE! | M25: -----------------------------------------------------------------------------------------------------------
A26: 30 | B26: 33 | C26: 36 | D26: 127 | E26: 0 | F26: 0 | G26: 0 | H26: 0 | I26: 90 | J26: 90 | K26: culvert Chinnamon crl low level opt" | L26: culvert Chinnamon crl low level opt | M26: 687905.490 7671197.460 0° 0' 0" 14750.000 148.510 10.977 147.269 -2.10 "CULVERTS FW Chinnamon option->culvert Chinnamon crl low level opt"
A27: #VALUE! | B27: #VALUE! | C27: #VALUE! | D27: #VALUE! | E27: #VALUE! | F27: #VALUE! | G27: #VALUE! | H27: #VALUE! | I27: #VALUE! | J27: #VALUE! | K27: #VALUE! | L27: #VALUE! | M27: -----------------------------------------------------------------------------------------------------------
A28: #VALUE! | B28: #VALUE! | C28: #VALUE! | D28: #VALUE! | E28: #VALUE! | F28: #VALUE! | G28: #VALUE! | H28: #VALUE! | I28: #VALUE! | J28: #VALUE! | K28: #VALUE! | L28: #VALUE! | M28: -----------------------------------------------------------------------------------------------------------
A29: #VALUE! | B29: #VALUE! | C29: 21 | D29: #VALUE! | E29: #VALUE! | F29: #VALUE! | G29: #VALUE! | H29: #VALUE! | I29: #VALUE! | J29: #VALUE! | K29: #VALUE! | L29: #VALUE! | M29: Road centre line "Gillian Creek"
A30: #VALUE! | B30: #VALUE! | C30: #VALUE! | D30: #VALUE! | E30: #VALUE! | F30: #VALUE! | G30: #VALUE! | H30: #VALUE! | I30: #VALUE! | J30: #VALUE! | K30: #VALUE! | L30: #VALUE! | M30: -----------------------------------------------------------------------------------------------------------
A31: #VALUE! | B31: #VALUE! | C31: #VALUE! | D31: #VALUE! | E31: #VALUE! | F31: #VALUE! | G31: #VALUE! | H31: #VALUE! | I31: #VALUE! | J31: #VALUE! | K31: #VALUE! | L31: #VALUE! | M31: Crossing Centreline String
A32: #VALUE! | B32: #VALUE! | C32: #VALUE! | D32: #VALUE! | E32: #VALUE! | F32: #VALUE! | G32: #VALUE! | H32: #VALUE! | I32: #VALUE! | J32: #VALUE! | K32: #VALUE! | L32: #VALUE! | M32: Easting Northing Angle Chainage Height Chainage Height Slope% Name
A33: #VALUE! | B33: #VALUE! | C33: #VALUE! | D33: #VALUE! | E33: #VALUE! | F33: #VALUE! | G33: #VALUE! | H33: #VALUE! | I33: #VALUE! | J33: #VALUE! | K33: #VALUE! | L33: #VALUE! | M33: -----------------------------------------------------------------------------------------------------------
A34: 30 | B34: 33 | C34: 36 | D34: 110 | E34: 16 | F34: 44 | G34: 37 | H34: 16.743611 | I34: 106.74361 | J34: 106.74361 | K34: culvert Gillam crk 001" | L34: culvert Gillam crk 001 | M34: 682975.952 7669843.586 16°44'37" 9393.431 138.600 7.684 137.682 -1.53 "CULVERTS FW->culvert Gillam crk 001"
A35: #VALUE! | B35: #VALUE! | C35: #VALUE! | D35: #VALUE! | E35: #VALUE! | F35: #VALUE! | G35: #VALUE! | H35: #VALUE! | I35: #VALUE! | J35: #VALUE! | K35: #VALUE! | L35: #VALUE! | M35: -----------------------------------------------------------------------------------------------------------
A36: #VALUE! | B36: #VALUE! | C36: #VALUE! | D36: #VALUE! | E36: #VALUE! | F36: #VALUE! | G36: #VALUE! | H36: #VALUE! | I36: #VALUE! | J36: #VALUE! | K36: #VALUE! | L36: #VALUE! | M36: -----------------------------------------------------------------------------------------------------------
A37: #VALUE! | B37: #VALUE! | C37: 21 | D37: #VALUE! | E37: #VALUE! | F37: #VALUE! | G37: #VALUE! | H37: #VALUE! | I37: #VALUE! | J37: #VALUE! | K37: #VALUE! | L37: #VALUE! | M37: Road centre line "Turner River West"
A38: #VALUE! | B38: #VALUE! | C38: #VALUE! | D38: #VALUE! | E38: #VALUE! | F38: #VALUE! | G38: #VALUE! | H38: #VALUE! | I38: #VALUE! | J38: #VALUE! | K38: #VALUE! | L38: #VALUE! | M38: -----------------------------------------------------------------------------------------------------------
A39: #VALUE! | B39: #VALUE! | C39: #VALUE! | D39: #VALUE! | E39: #VALUE! | F39: #VALUE! | G39: #VALUE! | H39: #VALUE! | I39: #VALUE! | J39: #VALUE! | K39: #VALUE! | L39: #VALUE! | M39: Crossing Centreline String
A40: #VALUE! | B40: #VALUE! | C40: #VALUE! | D40: #VALUE! | E40: #VALUE! | F40: #VALUE! | G40: #VALUE! | H40: #VALUE! | I40: #VALUE! | J40: #VALUE! | K40: #VALUE! | L40: #VALUE! | M40: Easting Northing Angle Chainage Height Chainage Height Slope% Name
...

Sheet PointsTidy - master
C1: {=IF(COUNTA(_xlfn.UNIQUE(_xlfn.ANCHORARRAY(B4)&_xlfn.ANCHORARRAY(C4)))<COUNTA(_xlfn.ANCHORARRAY(C4)),"DUPLICATES","")} -> DUPLICATES | W1: CHANGE CULVERT NAMES HERE (IF DESIRED) | Z1: SOURCE | AB1: 1d_nwk | AM1: raw name | AN1: adj name
B2: string name | C2: pit name | E2: invert us | F2: invert ds | G2: number of pipes | H2: diameter | I2: width | K2: width | L2: pit centre x | M2: pit centre y | T2: pipe type | AM2: {=_xlfn._xlws.SORT(_xlfn.UNIQUE(_xlfn.ANCHORARRAY(B4)))} -> R-1 | AN2: {=_xlfn.ANCHORARRAY(AM2)} -> R-1
A3: GroupID | B3: ID | C3: ends | D3: vertex_ind | E3: US_Invert | F3: DS_invert | G3: Number_of | H3: raw_diam | I3: raw_width | J3: Width_or_D | K3: Height_or_ | L3: xcoord | M3: ycoord | N3: zcoord | O3: MeasureLength | P3: AdjustedLength | Q3: dx | R3: dy | S3: dz | T3: Type | U3: Mannings | V3: Skew | W3: NewName | X3: Ctype | AM3: R-10 | AN3: R-10
A4: {=IF($AB$1="1d_nwk",_xlfn.ANCHORARRAY('PointsTidy -from 1dnwk'!A4),_xlfn.ANCHORARRAY('PointsTidy - 12D'!A4))} -> 1 | B4: {=IF($AB$1="1d_nwk",_xlfn.ANCHORARRAY('PointsTidy -from 1dnwk'!B4),_xlfn.ANCHORARRAY('PointsTidy - 12D'!B4))} -> R-1 | C4: {=IF($AB$1="1d_nwk",_xlfn.ANCHORARRAY('PointsTidy -from 1dnwk'!C4),_xlfn.ANCHORARRAY('PointsTidy - 12D'!C4))} -> R-1 | D4: {=IF($AB$1="1d_nwk",_xlfn.ANCHORARRAY('PointsTidy -from 1dnwk'!D4),_xlfn.ANCHORARRAY('PointsTidy - 12D'!D4))} -> 1 | E4: {=IF($AB$1="1d_nwk",_xlfn.ANCHORARRAY('PointsTidy -from 1dnwk'!E4),_xlfn.ANCHORARRAY('PointsTidy - 12D'!E4))} -> 398.32245 | F4: {=IF($AB$1="1d_nwk",_xlfn.ANCHORARRAY('PointsTidy -from 1dnwk'!F4),_xlfn.ANCHORARRAY('PointsTidy - 12D'!F4))} -> 395.86798 | G4: {=IF($AB$1="1d_nwk",_xlfn.ANCHORARRAY('PointsTidy -from 1dnwk'!G4),_xlfn.ANCHORARRAY('PointsTidy - 12D'!G4))} -> 5 | H4: {=IF($AB$1="1d_nwk",_xlfn.ANCHORARRAY('PointsTidy -from 1dnwk'!H4),_xlfn.ANCHORARRAY('PointsTidy - 12D'!H4))} -> MultiLineString ((687316.367809071787633 7565096.3571438966318965, 687240.47098323528189212 7565130.91730566136538982)) | ... V4: {=IF($AB$1="1d_nwk",_xlfn.ANCHORARRAY('PointsTidy -from 1dnwk'!V4),_xlfn.ANCHORARRAY('PointsTidy - 12D'!V4))} -> 90 | W4: {=IF(_xlfn.ANCHORARRAY(A4),VLOOKUP(_xlfn.ANCHORARRAY(B4),AM:AN,2,0))} -> R-1 | X4: {=IF($AB$1="1d_nwk",_xlfn.ANCHORARRAY('PointsTidy -from 1dnwk'!X4),_xlfn.ANCHORARRAY('PointsTidy - 12D'!X4))} -> C | AM4: R-10b | AN4: R-10b
A5: 1 | B5: R-1 | C5: R-1 | D5: 0 | E5: 398.32245 | F5: 395.86798 | G5: 5 | H5: MultiLineString ((687316.367809071787633 7565096.3571438966318965, 687240.47098323528189212 7565130.91730566136538982)) | I5: 1.5 | J5: 1.5 | K5: 0 | L5: 687316.37 | M5: 7565096.4 | N5: 395.86798 | O5: 83.395042 | P5: 83.395042 | Q5: 75.896826 | R5: -34.560162 | S5: -2.4544678 | T5: C | U5: 0.024 | V5: 90 | W5: R-1 | X5: C | AG5: These are #N/A error if not found on the import sheet | AM5: R-10c | AN5: R-10c
A6: 2 | B6: R-10 | C6: R-10 | D6: 1 | E6: 349.98645 | F6: 349.86862 | G6: 2 | H6: MultiLineString ((691801.30686036229599267 7569982.24155627377331257, 691774.55839837156236172 7569997.47331935167312622)) | I6: 1.2 | J6: 1.2 | K6: 0 | L6: 691774.56 | M6: 7569997.5 | N6: 349.98645 | O6: 30.781274 | P6: 30.781274 | Q6: 26.748462 | R6: -15.231763 | S6: -0.11782837 | T6: C | U6: 0.024 | V6: 90 | W6: R-10 | X6: C | AM6: R-11 | AN6: R-11
A7: 2 | B7: R-10 | C7: R-10 | D7: 0 | E7: 349.98645 | F7: 349.86862 | G7: 2 | H7: MultiLineString ((691801.30686036229599267 7569982.24155627377331257, 691774.55839837156236172 7569997.47331935167312622)) | I7: 1.2 | J7: 1.2 | K7: 0 | L7: 691801.31 | M7: 7569982.2 | N7: 349.86862 | O7: 30.781274 | P7: 30.781274 | Q7: 26.748462 | R7: -15.231763 | S7: -0.11782837 | T7: C | U7: 0.024 | V7: 90 | W7: R-10 | X7: C | AG7: The sheet expects 3 rows of titles, then the data | AM7: R-12 | AN7: R-12
A8: 3 | B8: R-10b | C8: R-10b | D8: 1 | E8: 351.56097 | F8: 351.14426 | G8: 2 | H8: MultiLineString ((691742.79459975729696453 7569821.37927791196852922, 691717.62504003697540611 7569824.07269943132996559)) | I8: 1.2 | J8: 1.2 | K8: 0 | L8: 691717.63 | M8: 7569824.1 | N8: 351.56097 | O8: 25.313262 | P8: 25.313262 | Q8: 25.16956 | R8: -2.6934215 | S8: -0.41671753 | T8: C | U8: 0.024 | V8: 90 | W8: R-10b | X8: C | AG8: the titles in row T need to be on row 2 of the import | AM8: R-13 | AN8: R-13
A9: 3 | B9: R-10b | C9: R-10b | D9: 0 | E9: 351.56097 | F9: 351.14426 | G9: 2 | H9: MultiLineString ((691742.79459975729696453 7569821.37927791196852922, 691717.62504003697540611 7569824.07269943132996559)) | I9: 1.2 | J9: 1.2 | K9: 0 | L9: 691742.79 | M9: 7569821.4 | N9: 351.14426 | O9: 25.313262 | P9: 25.313262 | Q9: 25.16956 | R9: -2.6934215 | S9: -0.41671753 | T9: C | U9: 0.024 | V9: 90 | W9: R-10b | X9: C | AM9: R-14 | AN9: R-14
A10: 4 | B10: R-10c | C10: R-10c | D10: 1 | E10: 353.09366 | F10: 352.65433 | G10: 1 | H10: MultiLineString ((691654.5618258296744898 7569630.88936283066868782, 691636.54376462753862143 7569647.32852176204323769)) | I10: 0.9 | J10: 0.9 | K10: 0 | L10: 691636.54 | M10: 7569647.3 | N10: 353.09366 | O10: 24.3905 | P10: 24.3905 | Q10: 18.018061 | R10: -16.439159 | S10: -0.43933105 | T10: C | U10: 0.024 | V10: 90 | W10: R-10c | X10: C | AG10: Type | AH10: mannings | AI10: pipet | AM10: R-14b | AN10: R-14b
A11: 4 | B11: R-10c | C11: R-10c | D11: 0 | E11: 353.09366 | F11: 352.65433 | G11: 1 | H11: MultiLineString ((691654.5618258296744898 7569630.88936283066868782, 691636.54376462753862143 7569647.32852176204323769)) | I11: 0.9 | J11: 0.9 | K11: 0 | L11: 691654.56 | M11: 7569630.9 | N11: 352.65433 | O11: 24.3905 | P11: 24.3905 | Q11: 18.018061 | R11: -16.439159 | S11: -0.43933105 | T11: C | U11: 0.024 | V11: 90 | W11: R-10c | X11: C | AG11: CSP | AH11: 0.024 | AI11: C | AM11: R-15 | AN11: R-15
A12: 5 | B12: R-11 | C12: R-11 | D12: 1 | E12: 348.3009 | F12: 348.02838 | G12: 3 | H12: MultiLineString ((691909.32235097035299987 7570320.73034003842622042, 691880.06622066791169345 7570339.67716728243976831)) | I12: 1.5 | J12: 1.5 | K12: 0 | L12: 691880.07 | M12: 7570339.7 | N12: 348.3009 | O12: 34.855465 | P12: 34.855465 | Q12: 29.25613 | R12: -18.946827 | S12: -0.27252197 | T12: C | U12: 0.024 | V12: 90 | W12: R-11 | X12: C | AG12: BC | AH12: 0.012 | AI12: R | AM12: R-16 | AN12: R-16
A13: 5 | B13: R-11 | C13: R-11 | D13: 0 | E13: 348.3009 | F13: 348.02838 | G13: 3 | H13: MultiLineString ((691909.32235097035299987 7570320.73034003842622042, 691880.06622066791169345 7570339.67716728243976831)) | I13: 1.5 | J13: 1.5 | K13: 0 | L13: 691909.32 | M13: 7570320.7 | N13: 348.02838 | O13: 34.855465 | P13: 34.855465 | Q13: 29.25613 | R13: -18.946827 | S13: -0.27252197 | T13: C | U13: 0.024 | V13: 90 | W13: R-11 | X13: C | AM13: R-17 | AN13: R-17
A14: 6 | B14: R-12 | C14: R-12 | D14: 1 | E14: 351.80154 | F14: 351.21353 | G14: 2 | H14: MultiLineString ((692036.69809301919303834 7570740.82406918331980705, 692012.72198079596273601 7570764.29275045823305845)) | I14: 0.9 | J14: 0.9 | K14: 0 | L14: 692012.72 | M14: 7570764.3 | N14: 351.80154 | O14: 33.550454 | P14: 33.550454 | Q14: 23.976112 | R14: -23.468681 | S14: -0.5880127 | T14: C | U14: 0.024 | V14: 90 | W14: R-12 | X14: C | AM14: R-17b | AN14: R-17b
A15: 6 | B15: R-12 | C15: R-12 | D15: 0 | E15: 351.80154 | F15: 351.21353 | G15: 2 | H15: MultiLineString ((692036.69809301919303834 7570740.82406918331980705, 692012.72198079596273601 7570764.29275045823305845)) | I15: 0.9 | J15: 0.9 | K15: 0 | L15: 692036.7 | M15: 7570740.8 | N15: 351.21353 | O15: 33.550454 | P15: 33.550454 | Q15: 23.976112 | R15: -23.468681 | S15: -0.5880127 | T15: C | U15: 0.024 | V15: 90 | W15: R-12 | X15: C | AM15: R-18 | AN15: R-18
A16: 7 | B16: R-13 | C16: R-13 | D16: 1 | E16: 344.2049 | F16: 343.79401 | G16: 4 | H16: MultiLineString ((692161.01794817426707596 7571146.96061041299253702, 692109.38757610891479999 7571160.85003517102450132)) | I16: 1.5 | J16: 1.5 | K16: 0 | L16: 692109.39 | M16: 7571160.9 | N16: 344.2049 | O16: 53.465984 | P16: 53.465984 | Q16: 51.630372 | R16: -13.889425 | S16: -0.41088867 | T16: C | U16: 0.024 | V16: 90 | W16: R-13 | X16: C | Z16: unique | AA16: =COUNTA(_xlfn.UNIQUE(_xlfn.ANCHORARRAY(W4))) -> 30 | AM16: R-18b | AN16: R-18b
A17: 7 | B17: R-13 | C17: R-13 | D17: 0 | E17: 344.2049 | F17: 343.79401 | G17: 4 | H17: MultiLineString ((692161.01794817426707596 7571146.96061041299253702, 692109.38757610891479999 7571160.85003517102450132)) | I17: 1.5 | J17: 1.5 | K17: 0 | L17: 692161.02 | M17: 7571147 | N17: 343.79401 | O17: 53.465984 | P17: 53.465984 | Q17: 51.630372 | R17: -13.889425 | S17: -0.41088867 | T17: C | U17: 0.024 | V17: 90 | W17: R-13 | X17: C | Z17: expected | AA17: =COUNTA(_xlfn.ANCHORARRAY(B4))/2 -> 30 | AM17: R-19 | AN17: R-19
A18: 8 | B18: R-14 | C18: R-14 | D18: 1 | E18: 342.7135 | F18: 342.29199 | G18: 4 | H18: MultiLineString ((692208.38501628290396184 7571615.61595487501472235, 692159.34616929991170764 7571613.57266958430409431)) | I18: 1.5 | J18: 1.5 | K18: 0 | L18: 692159.35 | M18: 7571613.6 | N18: 342.7135 | O18: 49.081397 | P18: 49.081397 | Q18: 49.038847 | R18: 2.0432853 | S18: -0.42150879 | T18: C | U18: 0.024 | V18: 90 | W18: R-14 | X18: C | AM18: R-2 | AN18: R-2
A19: 8 | B19: R-14 | C19: R-14 | D19: 0 | E19: 342.7135 | F19: 342.29199 | G19: 4 | H19: MultiLineString ((692208.38501628290396184 7571615.61595487501472235, 692159.34616929991170764 7571613.57266958430409431)) | I19: 1.5 | J19: 1.5 | K19: 0 | L19: 692208.39 | M19: 7571615.6 | N19: 342.29199 | O19: 49.081397 | P19: 49.081397 | Q19: 49.038847 | R19: 2.0432853 | S19: -0.42150879 | T19: C | U19: 0.024 | V19: 90 | W19: R-14 | X19: C | AM19: R-20 | AN19: R-20
A20: 9 | B20: R-14b | C20: R-14b | D20: 1 | E20: 346.563 | F20: 345.325 | G20: 1 | H20: MultiLineString ((692189.49452477414160967 7571443.62287487834692001, 692159.25583927519619465 7571463.08685634937137365)) | I20: 0.9 | J20: 0.9 | K20: 0 | L20: 692159.26 | M20: 7571463.1 | N20: 346.563 | O20: 35.961433 | P20: 35.961433 | Q20: 30.238685 | R20: -19.463981 | S20: -1.238 | T20: C | U20: 0.024 | V20: 90 | W20: R-14b | X20: C | AM20: R-21 | AN20: R-21
A21: 9 | B21: R-14b | C21: R-14b | D21: 0 | E21: 346.563 | F21: 345.325 | G21: 1 | H21: MultiLineString ((692189.49452477414160967 7571443.62287487834692001, 692159.25583927519619465 7571463.08685634937137365)) | I21: 0.9 | J21: 0.9 | K21: 0 | L21: 692189.49 | M21: 7571443.6 | N21: 345.325 | O21: 35.961433 | P21: 35.961433 | Q21: 30.238685 | R21: -19.463981 | S21: -1.238 | T21: C | U21: 0.024 | V21: 90 | W21: R-14b | X21: C | AM21: R-22 | AN21: R-22
A22: 10 | B22: R-15 | C22: R-15 | D22: 1 | E22: 344.97507 | F22: 344.4899 | G22: 2 | H22: MultiLineString ((692207.45625024160835892 7571762.91824903339147568, 692168.81958292168565094 7571777.40699927881360054)) | I22: 1.5 | J22: 1.5 | K22: 0 | L22: 692168.82 | M22: 7571777.4 | N22: 344.97507 | O22: 41.263979 | P22: 41.263979 | Q22: 38.636667 | R22: -14.48875 | S22: -0.48516846 | T22: C | U22: 0.024 | V22: 90 | W22: R-15 | X22: C | AM22: R-3 | AN22: R-3
A23: 10 | B23: R-15 | C23: R-15 | D23: 0 | E23: 344.97507 | F23: 344.4899 | G23: 2 | H23: MultiLineString ((692207.45625024160835892 7571762.91824903339147568, 692168.81958292168565094 7571777.40699927881360054)) | I23: 1.5 | J23: 1.5 | K23: 0 | L23: 692207.46 | M23: 7571762.9 | N23: 344.4899 | O23: 41.263979 | P23: 41.263979 | Q23: 38.636667 | R23: -14.48875 | S23: -0.48516846 | T23: C | U23: 0.024 | V23: 90 | W23: R-15 | X23: C | AM23: R-4 | AN23: R-4
A24: 11 | B24: R-16 | C24: R-16 | D24: 1 | E24: 347.94794 | F24: 347.10492 | G24: 1 | H24: MultiLineString ((692226.58883069327566773 7572259.15794492140412331, 692181.91518410469871014 7572253.02808904834091663)) | I24: 1.2 | J24: 1.2 | K24: 0 | L24: 692181.92 | M24: 7572253 | N24: 347.94794 | O24: 45.092237 | P24: 45.092237 | Q24: 44.673647 | R24: 6.1298559 | S24: -0.84301758 | T24: C | U24: 0.024 | V24: 90 | W24: R-16 | X24: C | AM24: R-5 | AN24: R-5
A25: 11 | B25: R-16 | C25: R-16 | D25: 0 | E25: 347.94794 | F25: 347.10492 | G25: 1 | H25: MultiLineString ((692226.58883069327566773 7572259.15794492140412331, 692181.91518410469871014 7572253.02808904834091663)) | I25: 1.2 | J25: 1.2 | K25: 0 | L25: 692226.59 | M25: 7572259.2 | N25: 347.10492 | O25: 45.092237 | P25: 45.092237 | Q25: 44.673647 | R25: 6.1298559 | S25: -0.84301758 | T25: C | U25: 0.024 | V25: 90 | W25: R-16 | X25: C | AM25: R-6 | AN25: R-6
A26: 12 | B26: R-17 | C26: R-17 | D26: 1 | E26: 337.30045 | F26: 337.15353 | G26: 2 | H26: MultiLineString ((692464.0743074647616595 7573334.20463777799159288, 692436.02557301614433527 7573348.69338802248239517)) | I26: 1.5 | J26: 1.5 | K26: 0 | L26: 692436.03 | M26: 7573348.7 | N26: 337.30045 | O26: 31.569849 | P26: 31.569849 | Q26: 28.048734 | R26: -14.48875 | S26: -0.14691162 | T26: C | U26: 0.024 | V26: 90 | W26: R-17 | X26: C | AM26: R-6b | AN26: R-6b
A27: 12 | B27: R-17 | C27: R-17 | D27: 0 | E27: 337.30045 | F27: 337.15353 | G27: 2 | H27: MultiLineString ((692464.0743074647616595 7573334.20463777799159288, 692436.02557301614433527 7573348.69338802248239517)) | I27: 1.5 | J27: 1.5 | K27: 0 | L27: 692464.07 | M27: 7573334.2 | N27: 337.15353 | O27: 31.569849 | P27: 31.569849 | Q27: 28.048734 | R27: -14.48875 | S27: -0.14691162 | T27: C | U27: 0.024 | V27: 90 | W27: R-17 | X27: C | AM27: R-7 | AN27: R-7
